package com.akka.future;

import akka.actor.ActorSystem;

import static akka.dispatch.Futures.future;

import java.util.concurrent.Callable;

import akka.dispatch.Mapper;
import akka.dispatch.Recover;
import scala.Tuple2;
import scala.concurrent.ExecutionContext;
import scala.concurrent.Future;

public class Future_Exceptions {
	ActorSystem system = ActorSystem.create("ActorSystem");

	public void test() {
		final ExecutionContext ec = system.dispatcher();
		Future<Integer> f1 =future(new Callable<Integer>() {

			@Override
			public Integer call(){
				
				return 1/0;
			}
		}, ec).recover(new Recover<Integer>() {

			@Override
			public Integer recover(Throwable problem) throws Throwable {
				return null;
			}
		}, ec);

				f4.onSuccess(new PrintResult<String>(), system.dispatcher());

	}

	public static void main(String[] args) {
		Future_Exceptions fm = new Future_Exceptions();
		fm.test();
	}

}
